# 可选链和错误处理

- [可选链和错误处理](#可选链和错误处理)
  - [可选链](#可选链)
    - [使用可选链式调用代替强制解包](#使用可选链式调用代替强制解包)
  - [错误处理](#错误处理)
    - [表示与抛出错误](#表示与抛出错误)
    - [处理错误](#处理错误)
    - [指定清理操作](#指定清理操作)

---

## 可选链

类似 Js 的 可选链

### 使用可选链式调用代替强制解包

可选链式调用提供了另一种访问 `numberOfRooms` 的方式，使用问号`（?）`来替代原来的叹号`（!）`：

```swift
let roomCount = john.residence!.numberOfRooms // 可能会报错

if let roomCount = john.residence?.numberOfRooms {
    print("John's residence has \(roomCount) room(s).")
} else {
    print("Unable to retrieve the number of rooms.")
}
// 打印“Unable to retrieve the number of rooms.”
```

## 错误处理

### 表示与抛出错误

```swift
enum VendingMachineError: Error {
    case invalidSelection                     //选择无效
    case insufficientFunds(coinsNeeded: Int) //金额不足
    case outOfStock                             //缺货
}
throw VendingMachineError.insufficientFunds(coinsNeeded: 5)
```

### 处理错误

**用 throwing 函数传递错误**

为了表示一个函数、方法或构造器可以抛出错误，在函数声明的参数之后加上 `throws` 关键字

```swift
func canThrowErrors() throws -> String
```

配合 `guard` 关键字使用，表示条件不满足直接抛出错误

```swift
struct Item {
    var price: Int
    var count: Int
}

class VendingMachine {
    var inventory = [
        "Candy Bar": Item(price: 12, count: 7),
        "Chips": Item(price: 10, count: 4),
        "Pretzels": Item(price: 7, count: 11)
    ]
    var coinsDeposited = 0

    func vend(itemNamed name: String) throws {
        guard let item = inventory[name] else {
            throw VendingMachineError.invalidSelection
        }

        guard item.count > 0 else {
            throw VendingMachineError.outOfStock
        }

        guard item.price <= coinsDeposited else {
            throw VendingMachineError.insufficientFunds(coinsNeeded: item.price - coinsDeposited)
        }

        coinsDeposited -= item.price

        var newItem = item
        newItem.count -= 1
        inventory[name] = newItem

        print("Dispensing \(name)")
    }
}
```

**用 Do-Catch 处理错误**

```swift
var vendingMachine = VendingMachine()
vendingMachine.coinsDeposited = 8
do {
  try buyFavoriteSnack(person: "Alice", vendingMachine: vendingMachine)
  print("Success! Yum.")
} catch VendingMachineError.invalidSelection {
  print("Invalid Selection.")
} catch VendingMachineError.outOfStock {
  print("Out of Stock.")
} catch VendingMachineError.insufficientFunds(let coinsNeeded) {
  print("Insufficient funds. Please insert an additional \(coinsNeeded) coins.")
} catch {
  print("Unexpected error: \(error).")
}

// 多个相关错误
func eat(item: String) throws {
    do {
        try vendingMachine.vend(itemNamed: item)
    } catch VendingMachineError.invalidSelection, VendingMachineError.insufficientFunds, VendingMachineError.outOfStock {
        print("Invalid selection, out of stock, or not enough money.")
    }
}
```

**将错误转换成可选值**

可以使用 `try?` 通过将错误转换成一个可选值来处理错误

```swift
func someThrowingFunction() throws -> Int {
    // ...
}

let x = try? someThrowingFunction()

let y: Int?
do {
    y = try someThrowingFunction()
} catch {
    y = nil
}
```

**禁用错误传递**

有时你知道某个 `throwing` 函数实际上在运行时是不会抛出错误的，在这种情况下，你可以在表达式前面写 `try!` 来禁用错误传递，这会把调用包装在一个不会有错误抛出的运行时断言中。

```swift
let photo = try! loadImage(atPath: "./Resources/John Appleseed.jpg")
```

### 指定清理操作

`defer` 关键字会在你离开函数体时执行，不管以什么样的方式。例如 `return`、`break`

```swift
func processFile(filename: String) throws {
    if exists(filename) {
        let file = open(filename)
        defer {
          // 确保离开后会关闭
            close(file)
        }
        while let line = try file.readline() {
            // 处理文件。
        }
        // close(file) 会在这里被调用，即作用域的最后。
    }
}
```
